Workbook

Sheet RDC+Niv Courants + Penthouse
A1: Récapitulatif Détaillée des surfaces - IMM R+4
A4: Client: Mr ZEBE | E4: Projet: Immeuble d'habitation R+4 - BASSAM
B6: RDC
B7: PIECES | C7: SURFACE | D7: ML | E7: Type Faux-plafond
B8: Entrée Extérieure Bâtiment | C8: 30.22 | E8: Hydrofuge
B9: TOILETTE | C9: 1.99 | E9: Hydrofuge
B10: TOILETTE | C10: 1.97 | E10: Hydrofuge
B11: TOILLETE | C11: 5.3 | E11: Hydrofuge
B12: BUREAU DU CONCIERGE | C12: 11.02 | E12: Standard
B13: COMMERCE | C13: 25.82 | E13: Standard
B14: DEGAGEMENT | C14: 26.25 | E14: Standard
B15: GUERITE | C15: 2.74 | E15: Standard
B16: HALL | C16: 16.78 | E16: Standard
B17: Sous-Total RDC | C17: =SUM(C8:C16) -> 122.09 | D17: 133.59
B18: NIVEAU 1
B19: PIECES | C19: SURFACE | D19: ML | E19: Type Faux-plafond
B20: BUANDERIE | C20: 3.47 | E20: Hydrofuge
B21: BALCON | C21: 12.28 | E21: Hydrofuge
B22: TOILETTE VISITEUR | C22: 1.82 | E22: Hydrofuge
B23: BUANDERIE | C23: 4.05 | E23: Hydrofuge
B24: BALCON | C24: 12.28 | E24: Hydrofuge
B25: TOILETTE VISITEUR | C25: 1.82 | E25: Hydrofuge
B26: CHAMBRE 3 | C26: 14.43 | E26: Standard
B27: CHAMBR2 2 | C27: 14.43 | E27: Standard
B28: CHAMBRE 1 | C28: 17.92 | E28: Standard
B29: DGT | C29: 4.37 | E29: Standard
B30: SEJOUR | C30: 35.91 | D30: 16.5 | E30: Standard
B31: CUISINE | C31: 10.04 | E31: Standard
B32: HALL | C32: 28.09 | E32: Standard
B33: SEJOUR | C33: 37.36 | D33: 16.5 | E33: Standard
B34: CUISINE | C34: 9.91 | E34: Standard
B35: CHAMBRE 3 | C35: 14.43 | E35: Standard
B36: CHAMBRE 2 | C36: 14.43 | E36: Standard
B37: CHAMBRE 1 | C37: 17.92 | E37: Standard
B38: DGT | C38: 4.37 | E38: Standard
B39: Sous-Total Niveau 1 | C39: =SUM(C20:C38) -> 259.33 | D39: =SUM(D20:D38) -> 33
B40: NIVEAU 2
B41: PIECES | C41: SURFACE | D41: ML | E41: Type Faux-plafond
B42: BUANDERIE | C42: 3.47 | E42: Hydrofuge
B43: BALCON | C43: 12.28 | E43: Hydrofuge
...

Sheet Devis détaillé
G8: Client: Mr ZEBE
A9: Objet: Offre de prix Faux-plafond - Immeuble Habitation R+4 - BASSAM
A10: Projet: Immeuble d'habitation R+4 - BASSAM | G10: Le 24/03/2021
B13: RDC
B14: PIECES | C14: SURFACE | D14: Unité | E14: Type Faux-plafond | F14: P.U HT MATERIEL | G14: Montant HT MATERIEL | H14: P.U HT MAIN D'ŒUVRE | I14: Montant HT MAIN D'ŒUVRE
B15: Entrée Extérieure Bâtiment | C15: 30.22 | D15: m² | E15: Hydrofuge | F15: 9000 | G15: =+F15*C15 -> 271980 | H15: 4000 | I15: =+H15*C15 -> 120880
B16: TOILETTE | C16: 1.99 | D16: m² | E16: Hydrofuge | F16: 9000 | G16: =+F16*C16 -> 17910 | H16: 4000 | I16: =+H16*C16 -> 7960
B17: TOILETTE | C17: 1.97 | D17: m² | E17: Hydrofuge | F17: 9000 | G17: =+F17*C17 -> 17730 | H17: 4000 | I17: =+H17*C17 -> 7880
B18: TOILLETE | C18: 5.3 | D18: m² | E18: Hydrofuge | F18: 9000 | G18: =+F18*C18 -> 47700 | H18: 4000 | I18: =+H18*C18 -> 21200
B19: BUREAU DU CONCIERGE | C19: 11.02 | D19: m² | E19: Standard | F19: 8000 | G19: =+F19*C19 -> 88160 | H19: 4000 | I19: =+H19*C19 -> 44080
B20: COMMERCE | C20: 25.82 | D20: m² | E20: Standard | F20: 8000 | G20: =+F20*C20 -> 206560 | H20: 4000 | I20: =+H20*C20 -> 103280
B21: DEGAGEMENT | C21: 26.25 | D21: m² | E21: Standard | F21: 8000 | G21: =+F21*C21 -> 210000 | H21: 4000 | I21: =+H21*C21 -> 105000
B22: GUERITE | C22: 2.74 | D22: m² | E22: Standard | F22: 8000 | G22: =+F22*C22 -> 21920 | H22: 4000 | I22: =+H22*C22 -> 10960
B23: HALL | C23: 16.78 | D23: m² | E23: Standard | F23: 8000 | G23: =+F23*C23 -> 134240 | H23: 4000 | I23: =+H23*C23 -> 67120
B24: Sous Total Surfaces RDC | C24: =SUM(C15:C23) -> 122.09 | D24: Sous-Total Matériels RDC | G24: =SUM(G15:G23) -> 1016200 | H24: Sous-Total Main D'Œuvre RDC | I24: =SUM(I15:I23) -> 488360
H25: Total HT MATERIEL et MAIN'ŒUVRE RDC | I25: =+G24+I24 -> 1504560
H26: TVA 18% | I26: =+I25*18% -> 270820.8
H27: Total TTC RDC | I27: =+I26+I25 -> 1775380.8
B28: NIVEAU Courant
B29: PIECES | C29: SURFACE | D29: Unité | E29: Type Faux-plafond | F29: P.U HT MATERIEL | G29: Montant HT MATERIEL | H29: P.U HT MAIN D'ŒUVRE | I29: Montant HT MAIN D'ŒUVRE
B30: BUANDERIE | C30: 3.47 | D30: m² | E30: Hydrofuge | F30: 9000 | G30: =+F30*C30 -> 31230 | H30: 4000 | I30: =+H30*C30 -> 13880
B31: BALCON | C31: 12.28 | D31: m² | E31: Hydrofuge | F31: 9000 | G31: =+F31*C31 -> 110520 | H31: 4000 | I31: =+H31*C31 -> 49120
B32: TOILETTE VISITEUR | C32: 1.82 | D32: m² | E32: Hydrofuge | F32: 9000 | G32: =+F32*C32 -> 16380 | H32: 4000 | I32: =+H32*C32 -> 7280
B33: BUANDERIE | C33: 4.05 | D33: m² | E33: Hydrofuge | F33: 9000 | G33: =+F33*C33 -> 36450 | H33: 4000 | I33: =+H33*C33 -> 16200
B34: BALCON | C34: 12.28 | D34: m² | E34: Hydrofuge | F34: 9000 | G34: =+F34*C34 -> 110520 | H34: 4000 | I34: =+H34*C34 -> 49120
B35: TOILETTE VISITEUR | C35: 1.82 | D35: m² | E35: Hydrofuge | F35: 9000 | G35: =+F35*C35 -> 16380 | H35: 4000 | I35: =+H35*C35 -> 7280
B36: CHAMBRE 3 | C36: 14.43 | D36: m² | E36: Standard | F36: 8000 | G36: =+F36*C36 -> 115440 | H36: 4000 | I36: =+H36*C36 -> 57720
B37: CHAMBR2 2 | C37: 14.43 | D37: m² | E37: Standard | F37: 8000 | G37: =+F37*C37 -> 115440 | H37: 4000 | I37: =+H37*C37 -> 57720
B38: CHAMBRE 1 | C38: 17.92 | D38: m² | E38: Standard | F38: 8000 | G38: =+F38*C38 -> 143360 | H38: 4000 | I38: =+H38*C38 -> 71680
B39: DGT | C39: 4.37 | D39: m² | E39: Standard | F39: 8000 | G39: =+F39*C39 -> 34960 | H39: 4000 | I39: =+H39*C39 -> 17480
B40: SEJOUR | C40: 35.91 | D40: m² | E40: Standard | F40: 8000 | G40: =+F40*C40 -> 287280 | H40: 4000 | I40: =+H40*C40 -> 143640
B41: CUISINE | C41: 10.04 | D41: m² | E41: Standard | F41: 8000 | G41: =+F41*C41 -> 80320 | H41: 4000 | I41: =+H41*C41 -> 40160
... B49: Séjour - Gorges | C49: 33 | D49: ml | E49: Gorge Lumineuse | F49: 4500 | G49: =+F49*C49 -> 148500 | H49: 2000 | I49: =+H49*C49 -> 66000
B50: Sous Total Etage 1 | C50: =SUM(C30:C48) -> 259.33 | D50: Sous-Total Matériels Etage 1 | G50: =SUM(G30:G49) -> 2258860 | H50: Sous-Total Main D'Œuvre Etage 1 | I50: =SUM(I30:I49) -> 1103320
H51: Total HT MATERIEL et MAIN'ŒUVRE Etage 1 | I51: =+I50+G50 -> 3362180
H52: TVA 18% | I52: =+I51*18% -> 605192.4
H53: Total TTC Etage 1 | I53: =+I52+I51 -> 3967372.4
B54: Sous Total Etage 2 | C54: =+C50 -> 259.33 | D54: Sous-Total Matériels Etage 2 | G54: =+G50 -> 2258860 | H54: Sous-Total Main D'Œuvre Etage 2 | I54: =+I50 -> 1103320
H55: Total HT MATERIEL et MAIN'ŒUVRE Etage 2 | I55: =+I54+G54 -> 3362180
H56: TVA 18% | I56: =+I55*18% -> 605192.4
...

Sheet Récap Matériel
A9: Objet: Offre de prix Faux-plafond - Immeuble Habitation R+4 - BASSAM
A10: Projet: Immeuble d'habitation R+4 - BASSAM
B13: RDC
B14: PIECES | C14: SURFACE | D14: Unité | E14: Type Faux-plafond
B15: Entrée Extérieure Bâtiment | C15: 30.22 | D15: m² | E15: Hydrofuge
B16: TOILETTE | C16: 1.99 | D16: m² | E16: Hydrofuge
B17: TOILETTE | C17: 1.97 | D17: m² | E17: Hydrofuge
B18: TOILLETE | C18: 5.3 | D18: m² | E18: Hydrofuge
B19: BUREAU DU CONCIERGE | C19: 11.02 | D19: m² | E19: Standard
B20: COMMERCE | C20: 25.82 | D20: m² | E20: Standard
B21: DEGAGEMENT | C21: 26.25 | D21: m² | E21: Standard
B22: GUERITE | C22: 2.74 | D22: m² | E22: Standard
B23: HALL | C23: 16.78 | D23: m² | E23: Standard
B24: Sous Total Surfaces RDC | C24: =SUM(C15:C23) -> 122.09 | D24: Sous-Total Matériels RDC
B28: NIVEAU Courant | H28: Projet GRADIAN
B29: PIECES | C29: SURFACE | D29: Unité | E29: Type Faux-plafond | G29: Appt 1 - Etage 1
B30: BUANDERIE | C30: 3.47 | D30: m² | E30: Hydrofuge | G30: Total Std | H30: =+C36+C37+C38+C39+C40+C41 -> 97.1 | I30: Matériel | J30: Quantités
B31: BALCON | C31: 12.28 | D31: m² | E31: Hydrofuge | G31: Total Hydro | H31: =+C30+C31+C32 -> 17.57 | I31: Cornières | J31: 73
B32: TOILETTE VISITEUR | C32: 1.82 | D32: m² | E32: Hydrofuge | G32: Total Gorges | H32: =+C49 -> 33 | I32: Chevilles à frapper | J32: 18
B33: BUANDERIE | C33: 4.05 | D33: m² | E33: Hydrofuge | I33: Chevilles laiton | J33: 230
B34: BALCON | C34: 12.28 | D34: m² | E34: Hydrofuge | I34: Tiges Filetées | J34: 115
B35: TOILETTE VISITEUR | C35: 1.82 | D35: m² | E35: Hydrofuge | I35: Cavaliers Pivots | J35: 230
B36: CHAMBRE 3 | C36: 14.43 | D36: m² | E36: Standard | I36: Fourrures | J36: 95
B37: CHAMBR2 2 | C37: 14.43 | D37: m² | E37: Standard | I37: Vis auto | J37: 1
B38: CHAMBRE 1 | C38: 17.92 | D38: m² | E38: Standard | I38: Eclisses | J38: 1
B39: DGT | C39: 4.37 | D39: m² | E39: Standard | I39: Plaques Standard | J39: 45
B40: SEJOUR | C40: 35.91 | D40: m² | E40: Standard | I40: Plaques Hydro | J40: 7
B41: CUISINE | C41: 10.04 | D41: m² | E41: Standard | I41: Vis 25 | J41: 2
B42: HALL | C42: 28.09 | D42: m² | E42: Standard | I42: Bande à joints | J42: 3
B43: SEJOUR | C43: 37.36 | D43: m² | E43: Standard | I43: Cornières perforées | J43: 13
B44: CUISINE | C44: 9.91 | D44: m² | E44: Standard | I44: 1/2 Cornière U | J44: 11
B45: CHAMBRE 3 | C45: 14.43 | D45: m² | E45: Standard | I45: Enduit de Joints | J45: 3
B46: CHAMBRE 2 | C46: 14.43 | D46: m² | E46: Standard
B47: CHAMBRE 1 | C47: 17.92 | D47: m² | E47: Standard
B48: DGT | C48: 4.37 | D48: m² | E48: Standard
B49: Séjour - Gorges | C49: 33 | D49: ml | E49: Gorge Lumineuse
B50: Sous Total Etage 1 | C50: =SUM(C30:C48) -> 259.33 | D50: Sous-Total Matériels Etage 1
B54: Sous Total Etage 2 | C54: =+C50 -> 259.33 | D54: Sous-Total Matériels Etage 2
B58: Sous Total Etage 3 | C58: =+C54 -> 259.33 | D58: Sous-Total Matériels Etage 3
B62: NIVEAU 4
...

Sheet Récap Surfaces Valorisé
A1: Client: Mr ZEBE | B1: Projet / Immeuble R+4 - BASSAM
A3: Travaux | B3: Zone | C3: Surface (m²) | D3: Linéaire (ml) | E3: PU HT | F3: Montant HT
A4: Faux-plafond Standrad en plaques BA13 sur ossature gavanisée Fourrure F530 | B4: RDC | C4: =+'RDC+Niv Courants + Penthouse'!C12+'RDC+Niv Courants + Penthouse'!C13+'RDC+Niv Courants + Penthouse'!C14+'RDC+Niv Courants + Penthouse'!C15+'RDC+Niv Courants + Penthouse'!C16 -> 82.61 | E4: 13000 | F4: =+E4*C4 -> 1073930
A5: Faux-plafond Hydrofuge en plaques BA13 sur ossature gavanisée Fourrure F530 | B5: RDC | C5: =+'RDC+Niv Courants + Penthouse'!C8+'RDC+Niv Courants + Penthouse'!C9+'RDC+Niv Courants + Penthouse'!C10+'RDC+Niv Courants + Penthouse'!C11 -> 39.48 | E5: 14000 | F5: =+E5*C5 -> 552720
A6: Faux-plafond Standrad en plaques BA13 sur ossature gavanisée Fourrure F530 | B6: Niveau 1 | C6: =+'RDC+Niv Courants + Penthouse'!C26+'RDC+Niv Courants + Penthouse'!C27+'RDC+Niv Courants + Penthouse'!C28+'RDC+Niv Courants + Penthouse'!C29+'RDC+Niv Courants + Penthouse'!C30+'RDC+Niv Courants + Penthouse'!C31+'RDC+Niv Courants + Penthouse'!C32+'RDC+Niv Courants + Penthouse'!C33+'RDC+Niv Courants + Penthouse'!C34+'RDC+Niv Courants + Penthouse'!C35+'RDC+Niv Courants + Penthouse'!C36+'RDC+Niv Courants + Penthouse'!C37+'RDC+Niv Courants + Penthouse'!C38 -> 223.61 | E6: 13000 | F6: =+E6*C6 -> 2906930
A7: Faux-plafond Hydrofuge en plaques BA13 sur ossature gavanisée Fourrure F530 | B7: Niveau 1 | C7: =+'RDC+Niv Courants + Penthouse'!C20+'RDC+Niv Courants + Penthouse'!C21+'RDC+Niv Courants + Penthouse'!C22+'RDC+Niv Courants + Penthouse'!C23+'RDC+Niv Courants + Penthouse'!C24+'RDC+Niv Courants + Penthouse'!C25 -> 35.72 | E7: 14000 | F7: =+E7*C7 -> 500080
A8: Fourniture et pose de Gorge Lumineuse à éclairage indirect | B8: Niveau 1 | D8: =+'RDC+Niv Courants + Penthouse'!D39 -> 33 | E8: 6500 | F8: =+E8*D8 -> 214500
A9: Faux-plafond Standrad en plaques BA13 sur ossature gavanisée Fourrure F530 | B9: Niveau 2 | C9: 223.61 | E9: 13000 | F9: =+E9*C9 -> 2906930
A10: Faux-plafond Hydrofuge en plaques BA13 sur ossature gavanisée Fourrure F530 | B10: Niveau 2 | C10: 35.72 | E10: 14000 | F10: =+E10*C10 -> 500080
A11: Fourniture et pose de Gorge Lumineuse à éclairage indirect | B11: Niveau 2 | D11: 33 | E11: 6500 | F11: =+E11*D11 -> 214500
A12: Faux-plafond Standrad en plaques BA13 sur ossature gavanisée Fourrure F530 | B12: Niveau 3 | C12: 223.61 | E12: 13000 | F12: =+E12*C12 -> 2906930
A13: Faux-plafond Hydrofuge en plaques BA13 sur ossature gavanisée Fourrure F530 | B13: Niveau 3 | C13: 35.72 | E13: 14000 | F13: =+E13*C13 -> 500080
A14: Fourniture et pose de Gorge Lumineuse à éclairage indirect | B14: Niveau 3 | D14: 33 | E14: 6500 | F14: =+E14*D14 -> 214500
A15: Faux-plafond Standrad en plaques BA13 sur ossature gavanisée Fourrure F530 | B15: Penthouse | C15: =+'RDC+Niv Courants + Penthouse'!C98+'RDC+Niv Courants + Penthouse'!C99+'RDC+Niv Courants + Penthouse'!C100+'RDC+Niv Courants + Penthouse'!C101+'RDC+Niv Courants + Penthouse'!C102+'RDC+Niv Courants + Penthouse'!C103+'RDC+Niv Courants + Penthouse'!C104+'RDC+Niv Courants + Penthouse'!C105+'RDC+Niv Courants + Penthouse'!C106+'RDC+Niv Courants + Penthouse'!C107 -> 187.78 | E15: 13000 | F15: =+E15*C15 -> 2441140
A16: Faux-plafond Hydrofuge en plaques BA13 sur ossature gavanisée Fourrure F530 | B16: Penthouse | C16: =+'RDC+Niv Courants + Penthouse'!C86+'RDC+Niv Courants + Penthouse'!C87+'RDC+Niv Courants + Penthouse'!C88+'RDC+Niv Courants + Penthouse'!C89+'RDC+Niv Courants + Penthouse'!C90+'RDC+Niv Courants + Penthouse'!C91+'RDC+Niv Courants + Penthouse'!C92+'RDC+Niv Courants + Penthouse'!C93+'RDC+Niv Courants + Penthouse'!C94+'RDC+Niv Courants + Penthouse'!C95+'RDC+Niv Courants + Penthouse'!C96+'RDC+Niv Courants + Penthouse'!C97 -> 83.53 | E16: 14000 | F16: =+E16*C16 -> 1169420
A17: Fourniture et pose de Gorge Lumineuse à éclairage indirect | B17: Penthouse | D17: =+'RDC+Niv Courants + Penthouse'!D107+'RDC+Niv Courants + Penthouse'!D105+'RDC+Niv Courants + Penthouse'!D102 -> 50.48 | E17: 6500 | F17: =+E17*D17 -> 328120
E18: Total HT | F18: =SUM(F4:F17) -> 16429860
E19: TVA | F19: =+F18*18% -> 2957374.8
E20: Total TTC | F20: =+F19+F18 -> 19387235

Sheet Récap Surface 
A1: RECAPITULATIF DES SURFACES
A3: Client: Mr ZEBE | B3: Projet / Immeuble R+4 - BASSAM
A5: Travaux | B5: Zone | C5: Surface (m²) | D5: Linéaire (ml)
A6: Faux-plafond Standrad en plaques BA13 sur ossature gavanisée Fourrure F530 | B6: RDC | C6: =+'RDC+Niv Courants + Penthouse'!C12+'RDC+Niv Courants + Penthouse'!C13+'RDC+Niv Courants + Penthouse'!C14+'RDC+Niv Courants + Penthouse'!C15+'RDC+Niv Courants + Penthouse'!C16 -> 82.61
A7: Faux-plafond Hydrofuge en plaques BA13 sur ossature gavanisée Fourrure F530 | B7: RDC | C7: =+'RDC+Niv Courants + Penthouse'!C8+'RDC+Niv Courants + Penthouse'!C9+'RDC+Niv Courants + Penthouse'!C10+'RDC+Niv Courants + Penthouse'!C11 -> 39.48
A8: Faux-plafond Standrad en plaques BA13 sur ossature gavanisée Fourrure F530 | B8: Niveau 1 | C8: =+'RDC+Niv Courants + Penthouse'!C26+'RDC+Niv Courants + Penthouse'!C27+'RDC+Niv Courants + Penthouse'!C28+'RDC+Niv Courants + Penthouse'!C29+'RDC+Niv Courants + Penthouse'!C30+'RDC+Niv Courants + Penthouse'!C31+'RDC+Niv Courants + Penthouse'!C32+'RDC+Niv Courants + Penthouse'!C33+'RDC+Niv Courants + Penthouse'!C34+'RDC+Niv Courants + Penthouse'!C35+'RDC+Niv Courants + Penthouse'!C36+'RDC+Niv Courants + Penthouse'!C37+'RDC+Niv Courants + Penthouse'!C38 -> 223.61
A9: Faux-plafond Hydrofuge en plaques BA13 sur ossature gavanisée Fourrure F530 | B9: Niveau 1 | C9: =+'RDC+Niv Courants + Penthouse'!C20+'RDC+Niv Courants + Penthouse'!C21+'RDC+Niv Courants + Penthouse'!C22+'RDC+Niv Courants + Penthouse'!C23+'RDC+Niv Courants + Penthouse'!C24+'RDC+Niv Courants + Penthouse'!C25 -> 35.72
A10: Fourniture et pose de Gorge Lumineuse à éclairage indirect | B10: Niveau 1 | D10: =+'RDC+Niv Courants + Penthouse'!D39 -> 33
A11: Faux-plafond Standrad en plaques BA13 sur ossature gavanisée Fourrure F530 | B11: Niveau 2 | C11: 223.61
A12: Faux-plafond Hydrofuge en plaques BA13 sur ossature gavanisée Fourrure F530 | B12: Niveau 2 | C12: 35.72
A13: Fourniture et pose de Gorge Lumineuse à éclairage indirect | B13: Niveau 2 | D13: 33
A14: Faux-plafond Standrad en plaques BA13 sur ossature gavanisée Fourrure F530 | B14: Niveau 3 | C14: 223.61
A15: Faux-plafond Hydrofuge en plaques BA13 sur ossature gavanisée Fourrure F530 | B15: Niveau 3 | C15: 35.72
A16: Fourniture et pose de Gorge Lumineuse à éclairage indirect | B16: Niveau 3 | D16: 33
A17: Faux-plafond Standrad en plaques BA13 sur ossature gavanisée Fourrure F530 | B17: Penthouse | C17: =+'RDC+Niv Courants + Penthouse'!C98+'RDC+Niv Courants + Penthouse'!C99+'RDC+Niv Courants + Penthouse'!C100+'RDC+Niv Courants + Penthouse'!C101+'RDC+Niv Courants + Penthouse'!C102+'RDC+Niv Courants + Penthouse'!C103+'RDC+Niv Courants + Penthouse'!C104+'RDC+Niv Courants + Penthouse'!C105+'RDC+Niv Courants + Penthouse'!C106+'RDC+Niv Courants + Penthouse'!C107 -> 187.78
A18: Faux-plafond Hydrofuge en plaques BA13 sur ossature gavanisée Fourrure F530 | B18: Penthouse | C18: =+'RDC+Niv Courants + Penthouse'!C86+'RDC+Niv Courants + Penthouse'!C87+'RDC+Niv Courants + Penthouse'!C88+'RDC+Niv Courants + Penthouse'!C89+'RDC+Niv Courants + Penthouse'!C90+'RDC+Niv Courants + Penthouse'!C91+'RDC+Niv Courants + Penthouse'!C92+'RDC+Niv Courants + Penthouse'!C93+'RDC+Niv Courants + Penthouse'!C94+'RDC+Niv Courants + Penthouse'!C95+'RDC+Niv Courants + Penthouse'!C96+'RDC+Niv Courants + Penthouse'!C97 -> 83.53
A19: Fourniture et pose de Gorge Lumineuse à éclairage indirect | B19: Penthouse | D19: =+'RDC+Niv Courants + Penthouse'!D107+'RDC+Niv Courants + Penthouse'!D105+'RDC+Niv Courants + Penthouse'!D102 -> 50.48
A20: Total | C20: =SUM(C6:C19) -> 1171.39 | D20: =SUM(D6:D19) -> 149.48
