Workbook

Sheet COTATION
A5: PLANS ARCHI CALLISTO ETOILE RDC
A6: PIÈCES | B6: M² | C6: ML
A7: CHAMBRE | B7: 12 | C7: 18.32 | E7: Les zones avec Joints Creux
A8: SE | B8: 3.27 | C8: 7.63
A9: SEJOUR/SAM | B9: 33.19 | C9: 25.26
A10: CUISINE | B10: 11.34 | C10: 13.5 | E10: Surfaces Sans JC | F10: =+B8+B10+B25+B19+B23+B24+B31+B32+#REF! -> #REF! | G10: =+F10+F11 -> #REF!
A11: TERRASSE 1 | B11: 7.47 | C11: 11.33 | E11: Surfaces avec JC | F11: =+B7+B9+B18+B20+B21+B22 -> 90.44
A12: TERRASSE 2 | B12: 6.3 | C12: =+B12*2 -> 12.6 | E12: Linéraires de JC | F12: =+C7+C9+C18+C20+C22 -> 95.53
A13: TOTAL | B13: =SUM(B7:B12) -> 73.57 | C13: =SUM(C7:C25) -> 99.1
A16: PLANS ARCHI CALLISTO ETOILE ETAGE
A17: PIÈCES | B17: M² | C17: ML
A18: CHAMBRE 1 | B18: 14.78 | C18: 16.46
A19: SE1 | B19: 4.04 | C19: 8.53
A20: CHAMBRE 2 | B20: 14.12 | C20: 17.49
A21: DRESSING | B21: 4.29 | C21: 8
A22: CHAMBRE 3 | B22: 12.06 | C22: 18
A23: SE 2 | B23: 3.67 | C23: 8.27
A24: SE 3 | B24: 3.31 | C24: 7.63
A25: ESCALIER | B25: 14.92 | C25: 12.4
A26: TOTAL | B26: =SUM(B18:B25) -> 71.19 | C26: =SUM(C18:C25) -> 96.78
A28: Total | B28: =+B26+B13 -> 144.76
A31: BALCON 1 | B31: 4.98 | C31: 10.25
A32: BALCON 2 | B32: 6.02 | C32: 11.49

Sheet MATERIELS
A2: Faux Plafond Standard Sans Joint Creux | F2: Faux Plafond Hydro Sans Joint Creux | K2: Faux Plafond LAMBRIS PVC BALCONS
C3: Surface (m²) | D3: =+COTATION!B10+COTATION!B25+COTATION!B21 -> 30.55 | H3: Surface (m²) | I3: =+COTATION!B8+COTATION!B11+COTATION!B12+COTATION!B19+COTATION!B23+COTATION!B24 -> 28.06 | M3: Surface (m²) | N3: =+'[1]COMMANDE_POUR_LA_COUVERTURE 4P'!$D$26+'[1]COMMANDE_POUR_LA_COUVERTURE 4P'!$D$27 -> 19.4985
A4: MATERIELS | B4: QUANTITÉ | C4: PRIX U. | D4: MONTANT HT | F4: MATERIELS | G4: QUANTITÉ | H4: PRIX U. | I4: MONTANT HT | K4: MATERIELS | L4: QUANTITÉ | M4: PRIX U. | N4: MONTANT HT
A5: CORNIERE | B5: 13 | C5: 910.68 | D5: =+B5*C5 -> 11838.84 | F5: CORNIERE | G5: 20 | H5: 910.68 | I5: =+G5*H5 -> 18213.6 | K5: CORNIERE | L5: 10 | M5: 910.68 | N5: =+L5*M5 -> 9106.8
A6: CHEVILLE A FRAPPER x30 | B6: 5 | C6: 885 | D6: =B6*C6 -> 4425 | F6: CHEVILLE A FRAPPER x30 | G6: 7 | H6: 885 | I6: =G6*H6 -> 6195 | K6: CHEVILLE A FRAPPER x30 | L6: 4 | M6: 885 | N6: =L6*M6 -> 3540
A7: FOURRURES | B7: 22 | C7: 1195 | D7: =+B7*C7 -> 26290 | F7: FOURRURES | G7: 20 | H7: 1195 | I7: =+G7*H7 -> 23900 | K7: FOURRURES | L7: 15 | M7: 1195 | N7: =+L7*M7 -> 17925
A8: CHEVILLE LAITON | B8: 25 | C8: 109.32 | D8: =+B8*C8 -> 2733 | F8: CHEVILLE LAITON | G8: 28 | H8: 109.32 | I8: =+G8*H8 -> 3060.96 | K8: SUSPENTES ARTICULÉE | L8: 0 | M8: 182.2 | N8: =+L8*M8 -> 0
A9: SUSPENTES ARTICULÉE | B9: 40 | C9: 182.2 | D9: =+B9*C9 -> 7288 | F9: SUSPENTES ARTICULÉE | G9: 0 | H9: 182.2 | I9: =+G9*H9 -> 0 | K9: TIGE 1M | L9: 0 | M9: 279.66 | N9: =+L9*M9 -> 0
A10: TIGE 1M | B10: 12 | C10: 279.66 | D10: =+B10*C10 -> 3355.92 | F10: TIGE 1M | G10: 14 | H10: 279.66 | I10: =+G10*H10 -> 3915.24 | K10: PIVOT | L10: 0 | M10: 81.72 | N10: =+L10*M10 -> 0
A11: TIGE 2M | B11: 38 | C11: 930 | D11: =+B11*C11 -> 35340 | F11: TIGE 2M | G11: 0 | H11: 930 | I11: =+G11*H11 -> 0 | K11: VIS AUTO | L11: 0.3 | M11: 6610.17 | N11: =+L11*M11 -> 1983.051
A12: PIVOT | B12: 65 | C12: 81.72 | D12: =+B12*C12 -> 5311.8 | F12: PIVOT | G12: 28 | H12: 81.72 | I12: =+G12*H12 -> 2288.16 | K12: Languette PVC/Unité | L12: 10 | M12: 2735 | N12: =+L12*M12 -> 27350
A13: ECLISSE | B13: 0.2 | C13: 10678.2 | D13: =+B13*C13 -> 2135.64 | F13: ECLISSE | G13: 0 | H13: 10678.2 | I13: =+G13*H13 -> 0 | K13: Lambris PVC/M² | L13: 24 | M13: 4000 | N13: =+L13*M13 -> 96000
A14: VIS AUTO | B14: 0.1 | C14: 6610.17 | D14: =+B14*C14 -> 661.017 | F14: VIS AUTO | G14: 0.12 | H14: 6610.17 | I14: =+G14*H14 -> 793.2204 | K14: VIS 25 | L14: 0.5 | M14: 3305.08 | N14: =+L14*M14 -> 1652.54
A15: PLAQUE HYDRO | B15: 0 | C15: 6610 | D15: =+B15*C15 -> 0 | F15: PLAQUE HYDRO | G15: 10 | H15: 6610 | I15: =+G15*H15 -> 66100 | L15: Total | M15: TOTAL HT | N15: =SUM(N5:N14) -> 157557.39
A16: PLAQUE standard | B16: 11 | C16: 5339 | D16: =+B16*C16 -> 58729 | F16: PLAQUE standard | G16: 0 | H16: 5339 | I16: =+G16*H16 -> 0 | M16: Estmation/M² | N16: =+N15/N3 -> 8080.4878
A17: VIS 25 | B17: 0.5 | C17: 3305.08 | D17: =+B17*C17 -> 1652.54 | F17: VIS 25 | G17: 0.5 | H17: 3305.08 | I17: =+G17*H17 -> 1652.54 | M17: Estmation MO/M² | N17: 1500
A18: ENDUIT | B18: 1 | C18: 8474.57 | D18: =+B18*C18 -> 8474.57 | F18: ENDUIT | G18: 1 | H18: 8474.57 | I18: =+G18*H18 -> 8474.57 | M18: Divers/M² | N18: 500
A19: BANDE A JOINT | B19: 0.5 | C19: 3813.55 | D19: =+B19*C19 -> 1906.775 | F19: BANDE A JOINT | G19: 0.5 | H19: 3813.55 | I19: =+G19*H19 -> 1906.775 | M19: Total Estimatif/M² | N19: =+N16+N17+N18 -> 10080.488
A20: CORNIERE PERFORÉE | B20: 0 | C20: 1101.69 | D20: =+B20*C20 -> 0 | F20: CORNIERE PERFORÉE | G20: 0 | H20: 1101.69 | I20: =+G20*H20 -> 0 | M20: Estimatif Vente/M² | N20: 12000
B21: Total | C21: TOTAL HT | D21: =SUM(D5:D20) -> 170142.1 | G21: Total | H21: TOTAL HT | I21: =SUM(I5:I20) -> 136500.07 | M21: Marge/M² | N21: =+N20-N19 -> 1919.5122
C22: Estmation/M² | D22: =+D21/D3 -> 5569.2996 | H22: Estmation/M² | I22: =+I21/I3 -> 4864.5782 | M22: Marge Totale 1 Villa | N22: =+N21*N3 -> 37427.609
C23: Estmation MO/M² | D23: 1850 | H23: Estmation MO/M² | I23: 1850 | M23: Marge Totale 56 Villa de 400m² | N23: =+N22*56 -> 2095946.1
C24: Divers/M² | D24: 750 | H24: Divers/M² | I24: 750
C25: Total Estimatif/M² | D25: =+D22+D23+D24 -> 8169.2996 | H25: Total Estimatif/M² | I25: =+I22+I23+I24 -> 7464.5782
C26: Estimatif Vente/M² | D26: 10500 | H26: Estimatif Vente/M² | I26: 11500
C27: Marge/M² | D27: =+D26-D25 -> 2330.7004 | H27: Marge/M² | I27: =+I26-I25 -> 4035.4218
C28: Marge Totale 1 Villa | D28: =+D27*D3 -> 71202.898 | H28: Marge Totale 1 Villa | I28: =+I27*I3 -> 113233.93
C29: Marge Totale 56 Villa de 400m² | D29: =+D28*56 -> 3987362.3 | H29: Marge Totale 56 Villa de 400m² | I29: =+I28*56 -> 6341100.3
A32: Faux Plafond Standard Sans Joint Creux
C33: Surface (m²) | D33: =+COTATION!B7+COTATION!B9+COTATION!B18+COTATION!B20+COTATION!B22 -> 86.15
A34: MATERIELS | B34: QUANTITÉ | C34: PRIX U. | D34: MONTANT HT
A35: CORNIERE | B35: 4 | C35: 910.68 | D35: =+B35*C35 -> 3642.72
A36: CHEVILLE A FRAPPER x30 | B36: 2 | C36: 885 | D36: =B36*C36 -> 1770
A37: FOURRURES | B37: 60 | C37: 1195 | D37: =+B37*C37 -> 71700
A38: CHEVILLE LAITON | B38: 90 | C38: 109.32 | D38: =+B38*C38 -> 9838.8
A39: SUSPENTES ARTICULÉE | B39: 85 | C39: 182.2 | D39: =+B39*C39 -> 15487
A40: TIGE 1M | B40: 45 | C40: 279.66 | D40: =+B40*C40 -> 12584.7
A41: TIGE 2M | B41: 65 | C41: 930 | D41: =+B41*C41 -> 60450
A42: PIVOT | B42: 175 | C42: 81.72 | D42: =+B42*C42 -> 14301
A43: ECLISSE | B43: 1 | C43: 10678.2 | D43: =+B43*C43 -> 10678.2
...

Sheet Etimatifs Matériel Joints Creux
A3: Matériels Joints Creux
C4: Longueurs | D4: 95.53
A5: MATERIELS | B5: QUANTITÉ | C5: PRIX U. | D5: MONTANT HT
A6: CORNIERE | B6: 34 | C6: 910.68 | D6: =+B6*C6 -> 30963.12
A7: Montants 48 | B7: 34 | C7: 1525 | D7: =+C7*B7 -> 51850
A8: CHEVILLE A FRAPPER x30 | B8: 12 | C8: 885 | D8: =B8*C8 -> 10620
A9: PLAQUE standard | B9: 5 | C9: 5339 | D9: =+B9*C9 -> 26695
A10: VIS 25 | B10: 1.5 | C10: 3305.08 | D10: =+B10*C10 -> 4957.62
A11: ENDUIT | B11: 1.5 | C11: 8474.57 | D11: =+B11*C11 -> 12711.855
A12: BANDE A JOINT | B12: 1 | C12: 3813.55 | D12: =+B12*C12 -> 3813.55
A13: Bande armée | B13: 4 | C13: 6102 | D13: =+B13*C13 -> 24408
B14: Total | C14: TOTAL HT | D14: =SUM(D6:D13) -> 166019.14
C15: Estmation/Ml | D15: =+D14/D4 -> 1737.8744
C16: Estmation MO/ml | D16: 650
C17: Divers/M² | D17: 0
C18: Total Estimatif/Ml | D18: =+D15+D16+D17 -> 2387.8744
C19: Estimatif Vente/M² | D19: 0
C20: Marge/M² | D20: 0
C21: Marge Totale 1 Villa | D21: 0
C22: Marge Totale 56 Villa de 400m² | D22: =+D21*56 -> 0

Sheet Récap détaillé Matériel Chiffré
A2: Faux Plafond Standard Sans Joint Creux | F2: Faux Plafond Hydro Sans Joint Creux | K2: Faux Plafond Plat Standard Dans les zones à joints Creux Joint Creux | P2: Matériels Joints Creux
C3: Surface (m²) | D3: =+COTATION!B10+COTATION!B25+COTATION!B21 -> 30.55 | H3: Surface (m²) | I3: =+COTATION!B8+COTATION!B11+COTATION!B12+COTATION!B19+COTATION!B23+COTATION!B24 -> 28.06 | M3: Surface (m²) | N3: 86.15 | R3: Longueurs | S3: 95.53
A4: MATERIELS | B4: QUANTITÉ | C4: PRIX U. | D4: MONTANT HT | F4: MATERIELS | G4: QUANTITÉ | H4: PRIX U. | I4: MONTANT HT | K4: MATERIELS | L4: QUANTITÉ | M4: PRIX U. | N4: MONTANT HT | P4: MATERIELS | Q4: QUANTITÉ | R4: PRIX U. | S4: MONTANT HT
A5: CORNIERE | B5: 13 | C5: 910.68 | D5: =+B5*C5 -> 11838.84 | F5: CORNIERE | G5: 20 | H5: 910.68 | I5: =+G5*H5 -> 18213.6 | K5: CORNIERE | L5: 4 | M5: 910.68 | N5: 3642.72 | P5: CORNIERE | Q5: 34 | R5: 910.68 | S5: 30963.12
A6: CHEVILLE A FRAPPER x30 | B6: 5 | C6: 885 | D6: =B6*C6 -> 4425 | F6: CHEVILLE A FRAPPER x30 | G6: 7 | H6: 885 | I6: =G6*H6 -> 6195 | K6: CHEVILLE A FRAPPER x30 | L6: 2 | M6: 885 | N6: 1770 | P6: Montants 48 | Q6: 34 | R6: 1525 | S6: 51850
A7: FOURRURES | B7: 22 | C7: 1195 | D7: =+B7*C7 -> 26290 | F7: FOURRURES | G7: 20 | H7: 1195 | I7: =+G7*H7 -> 23900 | K7: FOURRURES | L7: 60 | M7: 1195 | N7: 71700 | P7: CHEVILLE A FRAPPER x30 | Q7: 12 | R7: 885 | S7: 10620
A8: CHEVILLE LAITON | B8: 25 | C8: 109.32 | D8: =+B8*C8 -> 2733 | F8: CHEVILLE LAITON | G8: 28 | H8: 109.32 | I8: =+G8*H8 -> 3060.96 | K8: CHEVILLE LAITON | L8: 90 | M8: 109.32 | N8: 9838.8 | P8: PLAQUE standard | Q8: 5 | R8: 5339 | S8: 26695
A9: SUSPENTES ARTICULÉE | B9: 40 | C9: 182.2 | D9: =+B9*C9 -> 7288 | F9: SUSPENTES ARTICULÉE | G9: 0 | H9: 182.2 | I9: =+G9*H9 -> 0 | K9: SUSPENTES ARTICULÉE | L9: 85 | M9: 182.2 | N9: 15487 | P9: VIS 25 | Q9: 1.5 | R9: 3305.08 | S9: 4957.62
A10: TIGE 1M | B10: 12 | C10: 279.66 | D10: =+B10*C10 -> 3355.92 | F10: TIGE 1M | G10: 14 | H10: 279.66 | I10: =+G10*H10 -> 3915.24 | K10: TIGE 1M | L10: 45 | M10: 279.66 | N10: 12584.7 | P10: ENDUIT | Q10: 1.5 | R10: 8474.57 | S10: 12711.855
A11: TIGE 2M | B11: 38 | C11: 930 | D11: =+B11*C11 -> 35340 | F11: TIGE 2M | G11: 0 | H11: 930 | I11: =+G11*H11 -> 0 | K11: TIGE 2M | L11: 65 | M11: 930 | N11: 60450 | P11: BANDE A JOINT | Q11: 1 | R11: 3813.55 | S11: 3813.55
A12: PIVOT | B12: 65 | C12: 81.72 | D12: =+B12*C12 -> 5311.8 | F12: PIVOT | G12: 28 | H12: 81.72 | I12: =+G12*H12 -> 2288.16 | K12: PIVOT | L12: 175 | M12: 81.72 | N12: 14301 | P12: Bande armée | Q12: 4 | R12: 6102 | S12: 24408
A13: ECLISSE | B13: 0.2 | C13: 10678.2 | D13: =+B13*C13 -> 2135.64 | F13: ECLISSE | G13: 0 | H13: 10678.2 | I13: =+G13*H13 -> 0 | K13: ECLISSE | L13: 1 | M13: 10678.2 | N13: 10678.2
A14: VIS AUTO | B14: 0.1 | C14: 6610.17 | D14: =+B14*C14 -> 661.017 | F14: VIS AUTO | G14: 0.12 | H14: 6610.17 | I14: =+G14*H14 -> 793.2204 | K14: VIS AUTO | L14: 0.3 | M14: 6610.17 | N14: 1983.051
A15: PLAQUE HYDRO | B15: 0 | C15: 6610 | D15: =+B15*C15 -> 0 | F15: PLAQUE HYDRO | G15: 10 | H15: 6610 | I15: =+G15*H15 -> 66100 | K15: PLAQUE HYDRO | L15: 0 | M15: 6610 | N15: 0
A16: PLAQUE standard | B16: 11 | C16: 5339 | D16: =+B16*C16 -> 58729 | F16: PLAQUE standard | G16: 0 | H16: 5339 | I16: =+G16*H16 -> 0 | K16: PLAQUE standard | L16: 31 | M16: 5339 | N16: 165509
A17: VIS 25 | B17: 0.5 | C17: 3305.08 | D17: =+B17*C17 -> 1652.54 | F17: VIS 25 | G17: 0.5 | H17: 3305.08 | I17: =+G17*H17 -> 1652.54 | K17: VIS 25 | L17: 1.5 | M17: 3305.08 | N17: 4957.62
A18: ENDUIT | B18: 1 | C18: 8474.57 | D18: =+B18*C18 -> 8474.57 | F18: ENDUIT | G18: 1 | H18: 8474.57 | I18: =+G18*H18 -> 8474.57 | K18: ENDUIT | L18: 2 | M18: 8474.57 | N18: 16949.14
A19: BANDE A JOINT | B19: 0.5 | C19: 3813.55 | D19: =+B19*C19 -> 1906.775 | F19: BANDE A JOINT | G19: 0.5 | H19: 3813.55 | I19: =+G19*H19 -> 1906.775 | K19: BANDE A JOINT | L19: 1 | M19: 3813.55 | N19: 3813.55

Sheet Récap Générale Matériels
A2: Projet: CALLISTO
A4: RECAP GENERALE MATERIEL CALLISTO
A6: MATERIELS | B6: QUANTITÉ | C6: PRIX U. | D6: MONTANT HT
A7: CORNIERE | B7: 70 | C7: 910.68 | D7: 63747.6
A8: CHEVILLE A FRAPPER x30 | B8: 25 | C8: 885 | D8: 22125
A9: FOURRURES | B9: 100 | C9: 1195 | D9: 119500
A10: CHEVILLE LAITON | B10: 145 | C10: 109.32 | D10: 15851.4
A11: SUSPENTES ARTICULÉE | B11: 125 | C11: 182.2 | D11: 22775
A12: TIGE 1M | B12: 70 | C12: 279.66 | D12: 19576.2
A13: TIGE 2M | B13: 100 | C13: 930 | D13: 93000
A14: PIVOT | B14: 270 | C14: 81.72 | D14: 22064.4
A15: ECLISSE | B15: 1 | C15: 10678.2 | D15: 10678.2
A16: VIS AUTO | B16: 0.5 | C16: 6610.17 | D16: 3305.085
A17: PLAQUE HYDRO | B17: 10 | C17: 6610 | D17: 66100
A18: PLAQUE standard | B18: 47 | C18: 5339 | D18: 250933
... A23: Montant 48 | B23: 34 | C23: 1525 | D23: 51850
C24: Total Matériel HT | D24: 861422.28
C25: Est Mat/M² | D25: 5958.9255
C26: M/O Plaquiste | D26: ??
C27: M/O Jointeur 58*350 + 86*500 | D27: 70000
