Workbook

Sheet Feuil1
A1: ECM CI / SIMC CI
A3: Récapitulatif Surface
A4: Projet: FOFIE
A9: SOUS SOL
A10: HALL | B10: 27.3
A11: CH1 | B11: 14.59
A12: SDE CH1 | B12: 4
A13: CUISINE | B13: 52.8
A14: PERRON | B14: 3.95
A15: JEUX TV | B15: 14.76
A16: ESCALIER 3 | B16: 7.3
A17: ESCALIER 2 | B17: 12.5
A18: Hall | B18: 15.7
A19: TOILETTE | B19: 2.5
A20: ESCALIER 1 | B20: 13.11
A21: PARKING | B21: 122.43
A22: RAMPE D ACCESS | B22: 13
A23: Total Sous-Sol | B23: =SUM(B10:B22) -> 303.94
A24: RDC
A25: COURS DE SERVICE | B25: 17.33
A26: CUISINE | B26: 11.48
A27: TOILETTE | B27: 2.39
A28: CH 2 | B28: 11.44
A29: SAS 1 | B29: 7.15
A30: SALLE A MANGER | B30: 15.24
A31: TOILETTE | B31: 3.29
A32: DGT | B32: 7.76
A33: SEJOUR PRIVE | B33: 26.13
A34: BALCON | B34: 3.91
A35: ESCALIER | B35: 12.5
A36: DGT | B36: 11.18
... A43: ESCALIER 1 | B43: 12
A44: Total RDC | B44: =SUM(B25:B43) -> 307.76
A45: ETAGE 1
A46: SE | B46: 2.7
A47: BALCON | B47: 4.77
A48: CH 6 | B48: 15.39
A49: SE VI | B49: 2.04
A50: ESPACE | B50: 2.62
A51: BALCON | B51: 4.5
...

Sheet Détails Types FP- RDC
A2: Etude Estimative - Faux Plafond - Projet FOFIE
A4: Récap Surface | R4: Divers
C5: Faux-plafond BA13 STD | F5: Faux-plafond Hyd | I5: Caisson Suspendu Rectangle | L5: Caisson Suspendu Circulaire | O5: Corniches Périphériques | R5: Jouées Verticales | U5: Trappes de visites
A6: RDC | B6: Surface (m²) | C6: Longueur | D6: Largeur | E6: Surface | F6: Longueur | G6: Largeur | H6: Surface | I6: Longueur | J6: Largeur | K6: Surface | L6: Longueur | M6: Largeur | N6: Surface | O6: Longueur | P6: Largeur | Q6: Surface | R6: Longueur | S6: Largeur | T6: Surface | U6: Quantité
A7: COURS DE SERVICE | B7: 17.33 | E7: =+B7 -> 17.33
A8: DGT | B8: 11.18 | E8: =+B8 -> 11.18 | I8: 7.95 | J8: 0.4 | K8: =+J8*I8 -> 3.18
A9: CUISINE | B9: 11.48 | H9: =+B9 -> 11.48 | I9: 3.19 | J9: 1.41 | K9: =+J9*I9 -> 4.4979
A10: TOILETTE | B10: 2.39 | H10: =+B10 -> 2.39
A11: CH 2 | B11: 11.44 | E11: =+B11 -> 11.44 | I11: 2.1 | J11: 0.34 | K11: =+J11*I11 -> 0.714
A12: SAS 1 | B12: 7.15
A13: SALLE A MANGER | B13: 15.24 | E13: =+B13 -> 15.24 | I13: 1.56 | J13: 0.4 | K13: =+I13*J13*2 -> 1.248 | L13: 1.6 | M13: 1.6 | N13: =3.14*(0.8*0.8) -> 2.0096 | O13: =+(4.48*2)+(3.36*2) -> 15.68 | P13: 0.6 | Q13: =+P13*O13 -> 9.408
A14: TOILETTE | B14: 3.29 | H14: =+B14 -> 3.29
A15: DGT | B15: 7.76 | E15: =+B15 -> 7.76
A16: SEJOUR PRIVE | B16: 26.13 | E16: =+B16 -> 26.13 | I16: 2.99 | J16: 1.83 | K16: =+J16*I16 -> 5.4717 | O16: 18.96 | P16: 0.6 | Q16: =+P16*O16 -> 11.376
A17: BALCON | B17: 3.91 | H17: =+B17 -> 3.91
A18: ESCALIER | B18: 12.5 | E18: =+B18 -> 12.5
A19: TERRASSE 2 | B19: 27.55 | H19: =+B19 -> 27.55
A20: SUITE SEJOUR | B20: 13.59 | E20: =+B20 -> 13.59 | I20: 2.59 | J20: 1.49 | K20: =+J20*I20 -> 3.8591 | R20: =3.98+3.98+1.49+1.49 -> 10.94 | S20: 0.5 | T20: =+S20*R20 -> 5.47 | U20: 1
A21: SEJOUR | B21: 64.89 | E21: =+B21 -> 64.89 | K21: 7.91 | R21: =3.66+13.74+7.47+5.76 -> 30.63 | S21: 0.5 | T21: =+S21*R21 -> 15.315 | U21: 2
A22: TERRASSE TECHNIQUE | B22: 10.91 | H22: =+B22 -> 10.91
A23: TERRASSE 1 | B23: 19.4 | H23: =+B23 -> 19.4
A24: ESCALIER 1 | B24: 12 | E24: =+B24 -> 12
A25: Total RDC | C25: FP STD | E25: =SUM(E7:E24) -> 192.06 | F25: FP HYD | H25: =SUM(H7:H24) -> 78.93 | I25: =+(I20+I16+I13+I11+I9+I8+J8+J11+J9+J13+J16+J20)*2 -> 52.5 | K25: =SUM(K7:K24) -> 26.8807 | L25: Caisson Susp circulaire | N25: =SUM(N7:N24) -> 2.0096 | O25: =+(O16+O13+P13+P16)*2 -> 71.68 | Q25: =+O16+O13 -> 34.64 | R25: =+(R21+R20+S20+S21)*2 -> 85.14 | T25: =+R21+R20 -> 41.57 | U25: Trappes: 3
I26: Caisson Susp Rectangle | O26: Corniches (ml) | R26: Jouées Vertic. (ml)

Sheet Détails Types FP - Etage 1
A2: Etude Estimative - Faux Plafond - Projet FOFIE
A4: Récap Surface | R4: Divers
C5: Faux-plafond BA13 STD | F5: Faux-plafond Hyd | I5: Caisson Suspendu Rectangle | L5: Caisson Suspendu Circulaire | O5: Corniches Périphériques LED IND. | R5: Jouées Verticales | U5: Trappes de visites
A6: Etage 1 | B6: Surface (m²) | C6: Longueur | D6: Largeur | E6: Surface | F6: Longueur | G6: Largeur | H6: Surface | I6: Longueur | J6: Largeur | K6: Surface | L6: Longueur | M6: Largeur | N6: Surface | O6: Longueur | P6: Largeur | Q6: Surface | R6: Longueur | S6: Largeur | T6: Surface | U6: Quantité
A7: SE | B7: 2.7 | H7: =+B7 -> 2.7
A8: BALCON | B8: 4.77 | H8: =+B8 -> 4.77
A9: CH 6 | B9: 15.39 | E9: =+B9 -> 15.39 | O9: 6.1 | P9: 0.6 | Q9: =+P9*O9 -> 3.66
A10: SE VI | B10: 2.04 | H10: =+B10 -> 2.04
A11: ESPACE | B11: 2.62 | E11: =+B11 -> 2.62
A12: BALCON | B12: 4.5 | H12: =+B12 -> 4.5
A13: CH 5 | B13: 15.79 | E13: =+B13 -> 15.79 | O13: 2.91 | P13: 0.6 | Q13: =+P13*O13 -> 1.746 | R13: 4.11 | S13: 0.5 | T13: =+S13*R13 -> 2.055
A14: SE 5 | B14: 3.99 | H14: =+B14 -> 3.99
A15: SE 4 | B15: 3.99 | H15: =+B15 -> 3.99
A16: CH 4 | B16: 17.22 | E16: =+B16 -> 17.22 | O16: 6.78 | P16: 0.4 | Q16: =+P16*O16 -> 2.712 | R16: 4.11 | S16: 0.5 | T16: =+S16*R16 -> 2.055
A17: SE 3 | B17: 5.09 | H17: =+B17 -> 5.09
A18: CH 3 | B18: 23.84 | E18: =+B18 -> 23.84 | O18: 5.34 | P18: 0.6 | Q18: =+P18*O18 -> 3.204 | R18: 1.41 | S18: 0.5 | T18: =+S18*R18 -> 0.705
A19: BALCON CH 4 | B19: 10.93 | H19: =+B19 -> 10.93
A20: BALCON CH 3 | B20: 9.76 | H20: =+B20 -> 9.76
A21: BALCON CIRCU | B21: 5.31 | H21: =+B21 -> 5.31
A22: SALON FAMILLIAL | B22: 20.59 | E22: =+B22 -> 20.59 | I22: 14.48 | J22: 0.6 | K22: =+J22*I22 -> 8.688 | R22: =14.48+1.24+1.24+3.26+3.26 -> 23.48 | S22: 0.5 | T22: =+S22*R22 -> 11.74
A23: TERRASSE 2 | B23: 4.98 | H23: =+B23 -> 4.98
A24: DRESSING | B24: 14.6 | E24: =+B24 -> 14.6 | R24: 6.5 | S24: 0.5 | T24: =+S24*R24 -> 3.25
A25: DGT 1 | B25: 16.95 | E25: =+B25 -> 16.95 | O25: 13.52 | P25: 0.4 | Q25: =+P25*O25 -> 5.408
A26: DGT 2 | B26: 3.09 | E26: =+B26 -> 3.09
A27: ESCALIER | B27: 14 | E27: =+B27 -> 14
A28: CH PRIN | B28: 27.46 | E28: =+B28 -> 27.46 | O28: 10.08 | P28: 0.6 | Q28: =+P28*O28 -> 6.048 | R28: 6.34 | S28: 0.5 | T28: =+S28*R28 -> 3.17
A29: SE PRIN | B29: 14.6 | H29: =+B29 -> 14.6 | O29: 12.66 | P29: 0.6 | Q29: =+P29*O29 -> 7.596
A30: TERRASSE CH P | B30: 19.96 | H30: =+B30 -> 19.96
A31: ESCALIER | B31: 15 | E31: =+B31 -> 15
A32: Total Etage | C32: FP STD | E32: =SUM(E7:E31) -> 186.55 | F32: FP HYD | H32: =SUM(H7:H31) -> 92.62 | I32: =+(I22+J22)*2 -> 30.16 | K32: =SUM(K7:K31) -> 8.688 | L32: Caisson Susp circulaire | N32: =SUM(N7:N25) -> 0 | O32: =+(O29+O28+P29+P28+P25+O25+P18+O18+P16+O16+P13+O13+P9+O9)*2 -> 122.38 | Q32: =SUM(O7:O31) -> 57.39 | R32: =+(R28+S28+S24+R24+S22+R22+S18+R18+S16+R16+S13+R13)*2 -> 97.9 | T32: =SUM(R7:R31) -> 45.95 | U32: Trappes: 0
I33: Caisson Susp Rectangle | O33: Corniches (ml) | R33: Jouées Vertic. (ml)

Sheet Détails Type FP - Etage 2
A2: Etude Estimative - Faux Plafond - Projet FOFIE
A4: Récap Surface | R4: Divers
C5: Faux-plafond BA13 STD | F5: Faux-plafond Hyd | I5: Caisson Suspendu Rectangle | L5: Caisson Suspendu Circulaire | O5: Corniches Périphériques LED IND. | R5: Jouées Verticales | U5: Trappes de visites
A6: Etage 2 | B6: Surface (m²) | C6: Longueur | D6: Largeur | E6: Surface | F6: Longueur | G6: Largeur | H6: Surface | I6: Longueur | J6: Largeur | K6: Surface | L6: Longueur | M6: Largeur | N6: Surface | O6: Longueur | P6: Largeur | Q6: Surface | R6: Longueur | S6: Largeur | T6: Surface | U6: Quantité
A7: Terrasse Couverte | B7: 166
A8: BAR PRIVE | B8: 18.04 | E8: =+B8 -> 18.04 | I8: 2.3 | J8: 0.3 | K8: =+I8*J8*8 -> 5.52 | R8: 13.24 | S8: 0.5 | T8: =+S8*R8 -> 6.62
A9: TOILETTE | B9: 6.59 | H9: =+B9 -> 6.59
A10: SAS | B10: 3.9 | E10: =+B10 -> 3.9
A11: CH7 | B11: 19.28 | E11: =+B11 -> 19.28 | I11: 1.87 | J11: 0.4 | K11: =+J11*I11 -> 0.748 | O11: 17.56 | P11: 0.6 | Q11: =+P11*O11 -> 10.536
A12: BALCON | B12: 14.46 | H12: =+B12 -> 14.46
A13: ESCALIER 4 | B13: 12 | E13: =+B13 -> 12
A14: TOILETTE | B14: 11.25 | H14: =+B14 -> 11.25
A15: BUREAU | B15: =23.87+2.81 -> 26.68 | E15: =+B15 -> 26.68 | O15: 17.4 | P15: 0.6 | Q15: =+P15*O15 -> 10.44
A16: ESCALIER | B16: 9.5 | E16: =+B16 -> 9.5
A17: Total Etage | C17: FP STD | E17: =SUM(E8:E16) -> 89.4 | F17: FP HYD | H17: =SUM(H8:H16) -> 32.3 | I17: =+(I11+I8+J8+J11)*2 -> 9.74 | K17: =SUM(K8:K16) -> 6.268 | L17: Caisson Susp circulaire | N17: =SUM(N8:N16) -> 0 | O17: =+(O15+O11+P11+P15)*2 -> 72.32 | Q17: =+O15+O11 -> 34.96 | R17: =+(R8+S8)*2 -> 27.48 | T17: =SUM(R8:R16) -> 13.24 | U17: Trappes: 0
I18: Caisson Susp Rectangle | O18: Corniches (ml) | R18: Jouées Vertic. (ml)

Sheet Est. Mat. Par Type FP
C2: ETUDE ESTIMATIVE PROJET
B5: Projet: Villa FOFIE | J5: Divers
E6: Faux-plafond BA13 STD - m² | F6: Faux-plafond Hyd - m² | G6: Caisson Suspendu Rectangle - m² | H6: Caisson Suspendu Circulaire-m² | I6: Corniches Périphériques - ml | J6: Jouées Verticales - ml | K6: Trappes de visites - P
D7: Total Surface | E7: =SUM(E8:E10) -> 468.01 | F7: =SUM(F8:F10) -> 203.85 | G7: =SUM(G8:G10) -> 41.8367 | H7: =SUM(H8:H10) -> 2.0096 | I7: =SUM(I8:I10) -> 266.38 | J7: =SUM(J8:J10) -> 203.32 | K7: =SUM(K8:K10) -> 3
A8: Surface/Linéraire | B8: RDC | E8: =+'Détails Types FP- RDC'!E25 -> 192.06 | F8: =+'Détails Types FP- RDC'!H25 -> 78.93 | G8: =+'Détails Types FP- RDC'!K25 -> 26.8807 | H8: =+'Détails Types FP- RDC'!N25 -> 2.0096 | I8: 71.68 | J8: 85.14 | K8: 3
B9: Etage 1 | E9: =+'Détails Types FP - Etage 1'!E32 -> 186.55 | F9: =+'Détails Types FP - Etage 1'!H32 -> 92.62 | G9: =+'Détails Types FP - Etage 1'!K32 -> 8.688 | H9: =+'Détails Types FP - Etage 1'!N32 -> 0 | I9: 122.38 | J9: 90.7 | K9: 0
B10: Etage 2 | E10: =+'Détails Type FP - Etage 2'!E17 -> 89.4 | F10: =+'Détails Type FP - Etage 2'!H17 -> 32.3 | G10: =+'Détails Type FP - Etage 2'!K17 -> 6.268 | H10: 0 | I10: 72.32 | J10: 27.48 | K10: 0
B11: Total Matériel Projet | C11: PU HT | D11: Montant Total HT | E11: Quantité
A12: Cornières Périph. 3ml | B12: =SUM(E12:K12) -> 708 | C12: 910 | D12: =+C12*B12 -> 644280 | E12: 160 | F12: 70 | G12: 130 | H12: 8 | I12: 270 | J12: 70
A13: Chevilles à frapper*30 | B13: =SUM(E13:K13) -> 141 | C13: 885 | D13: =+C13*B13 -> 124785 | E13: 60 | F13: 25 | G13: 0 | H13: 1 | I13: 30 | J13: 25
A14: Chevilles Laiton | B14: =SUM(E14:K14) -> 1650 | C14: 109.32 | D14: =+C14*B14 -> 180378 | E14: =+E17*3 -> 960 | F14: =+F17*3 -> 420 | G14: 0 | H14: 0 | I14: =+I17*3 -> 270 | J14: 0
A15: Tiges filetées | B15: =SUM(E15:K15) -> 825 | C15: 279.66 | D15: =+C15*B15 -> 230719.5 | E15: =+E14/2 -> 480 | F15: =+F14/2 -> 210 | G15: 0 | H15: 0 | I15: =+I14/2 -> 135 | J15: 0
A16: Cavaliers Pivots | B16: =SUM(E16:K16) -> 1650 | C16: 81.72 | D16: =+C16*B16 -> 134838 | E16: =+E14 -> 960 | F16: =+F14 -> 420 | G16: 0 | H16: 0 | I16: =+I14 -> 270 | J16: 0
A17: Fourrures | B17: =SUM(E17:K17) -> 588 | C17: 1195 | D17: =+C17*B17 -> 702660 | E17: 320 | F17: 140 | G17: 35 | H17: 3 | I17: 90 | J17: 0
A18: Eclisse *50 | B18: =SUM(E18:K18) -> 4 | C18: 10678 | D18: =+C18*B18 -> 42712 | E18: 3 | F18: 1 | G18: 0 | H18: 0 | I18: 0 | J18: 0
A19: Vis Auto *1000 | B19: =SUM(E19:K19) -> 4 | C19: 6610 | D19: =+C19*B19 -> 26440 | E19: 2 | F19: 1 | G19: 0.5 | H19: 0 | I19: 0.5 | J19: 0
A20: Plaques Standard | B20: =SUM(E20:K20) -> 292 | C20: 5339 | D20: =+C20*B20 -> 1558988 | E20: 165 | F20: 0 | G20: 20 | H20: 2 | I20: 70 | J20: 35
A21: Plaques Hydro | B21: =SUM(E21:K21) -> 73 | C21: 6610 | D21: =+C21*B21 -> 482530 | E21: 0 | F21: 73 | G21: 0 | H21: 0 | I21: 0 | J21: 0
A22: Vis 25 * 1000 | B22: =SUM(E22:K22) -> 19 | C22: 3305 | D22: =+C22*B22 -> 62795 | E22: 8 | F22: 4 | G22: 1 | H22: 0 | I22: 4 | J22: 2
A23: Enduit de joint | B23: =SUM(E23:K23) -> 24.5 | C23: 8474 | D23: =+C23*B23 -> 207613 | E23: 10 | F23: 4 | G23: 2 | H23: 0.5 | I23: 5 | J23: 3
A24: Bande à joint | B24: =SUM(E24:K24) -> 11.5 | C24: 3813 | D24: =+C24*B24 -> 43849.5 | E24: 5 | F24: 2 | G24: 1 | H24: 0.5 | I24: 2 | J24: 1
A25: Cornières perforées | B25: =SUM(E25:K25) -> 197 | C25: 1101 | D25: =+C25*B25 -> 216897 | E25: 0 | F25: 0 | G25: 35 | H25: 2 | I25: 90 | J25: 70
A26: 1/2 Cornières perforées | B26: =SUM(E26:K26) -> 90 | C26: 1271 | D26: =+C26*B26 -> 114390 | E26: 0 | F26: 0 | G26: 0 | H26: 0 | I26: 90 | J26: 0
A27: Trappes de visite | B27: =SUM(E27:K27) -> 3 | C27: 25997 | D27: =+C27*B27 -> 77991 | E27: 3 | F27: 0 | G27: 0 | H27: 0 | I27: 0 | J27: 0
B28: Total HT Matériel | C28: =SUM(D12:D27) -> 4851866 | D28: PV HT | E28: 12500 | F28: 13500 | G28: 12000 | H28: 30000 | I28: 7000 | J28: 7000 | K28: 60000
B29: Est Main D'Œuvre et Divers Charges | C29: =+(E8+E9+E10+F8+F9+F10)*3000 -> 2015580 | D29: Montant Vente HT | E29: =+E28*(E8+E9+E10) -> 5850125 | F29: =+F28*(F8+F9+F10) -> 2751975 | G29: =+G28*(G8+G9+G10) -> 502040.4 | H29: =+H28*(H8+H9+H10) -> 60288 | I29: =+I28*(I8+I9+I10) -> 1864660 | J29: =+J28*(J8+J9+J10) -> 1423240 | K29: =+K28*(K8+K9+K10) -> 180000
B30: Total Estimatif Mat & M.O | C30: =+C28+C29 -> 6867446
D32: Montant Total Vente HT | E32: =SUM(E29:K29) -> 12632328
D33: Estimatif Marge | E33: =+E32-C30 -> 5764882.4
D34: % Marge | E34: =+E33/E32 -> 0.45635945

Sheet Récap Matériels
C2: Récap Matériel ESTIMATIFPROJET
B5: VILLA FOFIE | H5: Divers
C6: Faux-plafond BA13 STD - m² | D6: Faux-plafond Hyd - m² | E6: Caisson Suspendu Rectangle - m² | F6: Caisson Suspendu Circulaire-m² | G6: Corniches Périphériques - ml | H6: Jouées Verticales - ml | I6: Trappes de visites - P
B7: Total Surface | C7: =SUM(C8:C10) -> 468.01 | D7: =SUM(D8:D10) -> 203.85 | E7: =SUM(E8:E10) -> 41.8367 | F7: =SUM(F8:F10) -> 2.0096 | G7: =SUM(G8:G10) -> 266.38 | H7: =SUM(H8:H10) -> 203.32 | I7: =SUM(I8:I10) -> 3
A8: Surface/Linéraire | B8: RDC | C8: =+'Détails Types FP- RDC'!E25 -> 192.06 | D8: =+'Détails Types FP- RDC'!H25 -> 78.93 | E8: =+'Détails Types FP- RDC'!K25 -> 26.8807 | F8: =+'Détails Types FP- RDC'!N25 -> 2.0096 | G8: 71.68 | H8: 85.14 | I8: 3
B9: Etage 1 | C9: =+'Détails Types FP - Etage 1'!E32 -> 186.55 | D9: =+'Détails Types FP - Etage 1'!H32 -> 92.62 | E9: =+'Détails Types FP - Etage 1'!K32 -> 8.688 | F9: =+'Détails Types FP - Etage 1'!N32 -> 0 | G9: 122.38 | H9: 90.7 | I9: 0
B10: Etage 2 | C10: =+'Détails Type FP - Etage 2'!E17 -> 89.4 | D10: =+'Détails Type FP - Etage 2'!H17 -> 32.3 | E10: =+'Détails Type FP - Etage 2'!K17 -> 6.268 | F10: 0 | G10: 72.32 | H10: 27.48 | I10: 0
B11: Total Matériel Projet | C11: Quantité
A12: Cornières Périph. 3ml | B12: =SUM(C12:I12) -> 708 | C12: 160 | D12: 70 | E12: 130 | F12: 8 | G12: 270 | H12: 70
A13: Chevilles à frapper*30 | B13: =SUM(C13:I13) -> 141 | C13: 60 | D13: 25 | E13: 0 | F13: 1 | G13: 30 | H13: 25
A14: Chevilles Laiton | B14: =SUM(C14:I14) -> 1650 | C14: =+C17*3 -> 960 | D14: =+D17*3 -> 420 | E14: 0 | F14: 0 | G14: =+G17*3 -> 270 | H14: 0
A15: Tiges filetées | B15: =SUM(C15:I15) -> 825 | C15: =+C14/2 -> 480 | D15: =+D14/2 -> 210 | E15: 0 | F15: 0 | G15: =+G14/2 -> 135 | H15: 0
A16: Cavaliers Pivots | B16: =SUM(C16:I16) -> 1650 | C16: =+C14 -> 960 | D16: =+D14 -> 420 | E16: 0 | F16: 0 | G16: =+G14 -> 270 | H16: 0
A17: Fourrures | B17: =SUM(C17:I17) -> 588 | C17: 320 | D17: 140 | E17: 35 | F17: 3 | G17: 90 | H17: 0
A18: Eclisse *50 | B18: =SUM(C18:I18) -> 4 | C18: 3 | D18: 1 | E18: 0 | F18: 0 | G18: 0 | H18: 0
A19: Vis Auto *1000 | B19: =SUM(C19:I19) -> 4 | C19: 2 | D19: 1 | E19: 0.5 | F19: 0 | G19: 0.5 | H19: 0
A20: Plaques Standard | B20: =SUM(C20:I20) -> 292 | C20: 165 | D20: 0 | E20: 20 | F20: 2 | G20: 70 | H20: 35
A21: Plaques Hydro | B21: =SUM(C21:I21) -> 73 | C21: 0 | D21: 73 | E21: 0 | F21: 0 | G21: 0 | H21: 0
A22: Vis 25 * 1000 | B22: =SUM(C22:I22) -> 19 | C22: 8 | D22: 4 | E22: 1 | F22: 0 | G22: 4 | H22: 2
A23: Enduit de joint | B23: =SUM(C23:I23) -> 24.5 | C23: 10 | D23: 4 | E23: 2 | F23: 0.5 | G23: 5 | H23: 3
A24: Bande à joint | B24: =SUM(C24:I24) -> 11.5 | C24: 5 | D24: 2 | E24: 1 | F24: 0.5 | G24: 2 | H24: 1
A25: Cornières perforées | B25: =SUM(C25:I25) -> 197 | C25: 0 | D25: 0 | E25: 35 | F25: 2 | G25: 90 | H25: 70
A26: 1/2 Cornières perforées | B26: =SUM(C26:I26) -> 90 | C26: 0 | D26: 0 | E26: 0 | F26: 0 | G26: 90 | H26: 0
A27: Trappes de visite | B27: =SUM(C27:I27) -> 3 | C27: 3 | D27: 0 | E27: 0 | F27: 0 | G27: 0 | H27: 0
