Workbook

Sheet Récap Etude Estimative
A2: Récap. Estimatif PROCREA
A6: Type de travaux | B6: Etimatif Revient HT/m² | C6: P.V U HT | D6: Marge Estimative sur Surface réelle HT | E6: Valeur Surfacturation HT | F6: Marge totale HT
A7: Cloisons 96/70 HYD | B7: =+'Etude détaillée estimative'!D26 -> 11469.912 | C7: =+'Etude détaillée estimative'!D27 -> 16500 | D7: =+'Etude détaillée estimative'!D29 -> 5321833 | E7: =+'Etude détaillée estimative'!D30 -> 873015 | F7: =+E7+D7 -> 6194848
A8: Doublage | B8: =+'Etude détaillée estimative'!D54 -> 6493.7273 | C8: 11000 | D8: =+'Etude détaillée estimative'!D57 -> 1685346 | E8: =+'Etude détaillée estimative'!D58 -> 205810 | F8: =+E8+D8 -> 1891156
A9: Geberit 2 Peaux HYD | B9: =+'Etude détaillée estimative'!D82 -> 9182.2583 | C9: 12500 | D9: =+'Etude détaillée estimative'!D85 -> 716632.2 | E9: =+'Etude détaillée estimative'!D86 -> 1526125 | F9: =+E9+D9 -> 2242757.2
A10: Linteaux Double Ossature | B10: =+'Etude détaillée estimative'!D110 -> 14703.79 | C10: 18000 | D10: =+'Etude détaillée estimative'!D113 -> 331368 | E10: =+'Etude détaillée estimative'!D114 -> 813420 | F10: =+E10+D10 -> 1144788
A11: Total | C11: 29510939 | D11: =SUM(D7:D10) -> 8055179.2 | E11: =SUM(E7:E10) -> 3418370 | F11: =SUM(F7:F10) -> 11473549
E12: Valeur Commission | F12: 1500000
E13: Marge Nette | F13: =+F11-F12 -> 9973549.2
E14: Taux de Marge | F14: =+F13/C11 -> 0.33796109

Sheet Etude détaillée estimative
A2: Estimatif PROCREA
A6: Estimatifs Matériels: Cloisons Ep. 10Cm avec 1 isolants 45mm
B8: Surface Estimative m² | D8: 1058
B9: Hauteur Estimative | D9: 3.38
B10: Linéaire Estimative | D10: =+D8/D9 -> 313.01775
B12: Quantité | C12: PU HT | D12: Montant HT
A13: Rail 70 3ml | B13: 210 | C13: 2118 | D13: =+C13*B13 -> 444780
A14: Montant 70 2,5ml | B14: 690 | C14: 2415 | D14: =+C14*B14 -> 1666350
A15: Cheville à frapper *30 | B15: =+((B13*3)/0.3)/30 -> 70 | C15: 885 | D15: =+C15*B15 -> 61950
A16: Vis auto *1000 | B16: 3 | C16: 6610 | D16: =+C16*B16 -> 19830
A17: Laine de verre 45mm 14,4 | B17: 75 | C17: 30000 | D17: =+C17*B17 -> 2250000
A18: Plaques de plâtre BA13 2,5*1,2 Hydro | B18: =+(D8*2*1.05)/3 -> 740.6 | C18: 6610 | D18: =+C18*B18 -> 4895366
A19: Vis 25 *1000 | B19: 35 | C19: 3305 | D19: =+C19*B19 -> 115675
A20: Enduit de joint | B20: 45 | C20: 8474 | D20: =+C20*B20 -> 381330
A21: Bande à joint | B21: 22 | C21: 3813 | D21: =+C21*B21 -> 83886
A22: Cornière perforée | B22: 100 | C22: 1000 | D22: =+C22*B22 -> 100000
B23: Sans Enduit de finition | C23: Total HT | D23: =SUM(D13:D22) -> 10019167
C24: Total Mat/M² | D24: =+D23/D8 -> 9469.9121
C25: Est MO/M² | D25: 2000
C26: Total EST/M² | D26: =+D25+D24 -> 11469.912
C27: Est Vente.m² | D27: 16500
C28: Marge est./M² | D28: =+D27-D26 -> 5030.0879
C29: Marge est totale | D29: =+D28*D8 -> 5321833
C30: Surplus Facturation | D30: 873015
C31: Marge après refacturation | D31: =+D30+D29 -> 6194848
A34: Estimatifs Matériels: Doublage
B36: Surface Estimative m² | D36: 374
B37: Hauteur Estimative | D37: 3.38
B38: Linéaire Estimative | D38: =+D36/D37 -> 110.65089
B40: Quantité | C40: PU HT | D40: Montant HT
A41: Rail 48 3ml | B41: 80 | C41: 1525 | D41: =+C41*B41 -> 122000
A42: Montant 48 2,5ml | B42: 390 | C42: 1525 | D42: =+C42*B42 -> 594750
A43: Cheville à frapper *30 | B43: 28 | C43: 885 | D43: =+C43*B43 -> 24780
A44: Vis auto *1000 | B44: 3 | C44: 6610 | D44: =+C44*B44 -> 19830
A45: Laine de verre 45mm 14,4 | B45: 0 | C45: 30000 | D45: =+C45*B45 -> 0
A46: Plaques de plâtre BA13 2,5*1,2 Hydro | B46: 132 | C46: 6610 | D46: =+C46*B46 -> 872520
A47: Vis 25 *1000 | B47: 6 | C47: 3305 | D47: =+C47*B47 -> 19830
A48: Enduit de joint | B48: 8 | C48: 8474 | D48: =+C48*B48 -> 67792
A49: Bande à joint | B49: 4 | C49: 3813 | D49: =+C49*B49 -> 15252
A50: Cornière perforée | B50: 0 | C50: 1000 | D50: =+C50*B50 -> 0
...
